Workbook
Name NativeTimeline_ApplicationDate: #N/A
Name Slicer_Branch: #N/A
Name Slicer_Channel: #N/A
Name Slicer_Product: #N/A
Name Slicer_Segment: #N/A

Sheet Dashboard

Sheet Answer
A1: Question | B1: Answer
A2: D1 | B2: Jahra approval rate: Jan–May = 72.8% vs Jun–Sep = 43.1% → a drop of ~29.7 percentage points.
B3: Before June, Jahra was above the bank average (71.8%); from June it fell far below it.
B4: The drop is clear across all channels (Mobile App and Branch fell the most), approved deals fell from 59 to 31, and the average decision time rose from 8.0 to 10.9 days.
B5: Possible cause: a change at the branch from June (new credit officer/policy, stricter approval rules, or staff shortage) — needs to be investigated with the branch manager.
A6: D2 | B6: For Personal Tawarruq, Mobile App has the lowest approval rate: 66.1% (vs Branch 79.2% and Online 75.4%; product average 75.3%).
B7: That is ~13 points below Branch — Mobile App applications for this product are rejected much more often.
B8: Possible cause: weaker document/eligibility checks in the app (incomplete salary info, applicants not meeting criteria) before submission.
A9: D3 | B9: Total approved amount for Premium segment in Q3 (Jul–Sep): 1,578,800 KWD from 32 approved deals.
B10: This is ~32% of Premium's total approved amount for Jan–Sep (4,947,600 KWD).
B11: Premium has a high average deal size (49,338 KWD vs bank average 39,047 KWD), but approvals dropped sharply in September compared to July and August.
A12: D4 | B12: Auto Murabaha had its highest approved amount in August: 581,300 KWD (July was almost the same at 578,000 KWD), compared with roughly 200,000–450,000 KWD in other months.
B13: Possible reasons: summer is peak car-buying season in Kuwait — new model-year cars are launched mid-year, dealers run summer offers, and families buy cars before the new school year (September).
B14: Action: prepare more Auto Murabaha capacity and joint dealer promotions for Jul–Aug.
A15: D5 | B15: Home Ijara takes 20.2 days on average to reach a decision, vs 5.7 days for the other three products — about 3.5x longer (+14.5 days).
B16: Home Ijara also has a lower approval rate (63.6% vs 73.0%) and much bigger deals (avg ~156K KWD vs ~25K KWD).
B17: Reason: home financing needs property valuation, title/ownership documents and higher approval authority, so it naturally takes longer — but 20 days is a risk of losing customers to faster banks.
A18: D6 | B18: Recommendation 1 – Jahra branch
B19: Observation: Jahra's approval rate dropped sharply from June.
B20: Number: 72.8% (Jan–May) → 43.1% (Jun–Sep), a drop of ~30 points; approved deals fell from 59 to 31 and decision time rose from 8.0 to 10.9 days.
B21: Action: Review what changed at Jahra in June (staff, credit officer, local policy) with the branch manager, audit a sample of rejected applications, and track Jahra's approval rate weekly on this dashboard.
B23: Recommendation 2 – Mobile App channel
B24: Observation: Mobile App has the lowest approval rate of all channels.
B25: Number: 64.5% vs Branch 75.0% and Online 73.1%; for Personal Tawarruq it is 66.1% vs 79.2% at Branch.
B26: Action: Add eligibility checks inside the app before submission (minimum salary, required documents, debt ratio) and show customers a pre-approval estimate, to reduce rejected applications and wasted processing time.
B28: Recommendation 3 – Home Ijara decision time
B29: Observation: Home Ijara decisions are much slower than other products.
B30: Number: 20.2 days on average vs 5.7 days for the other products (~3.5x longer), with the largest deal size (~156K KWD).
B31: Action: Set a target of ≤ 10 days by creating a dedicated Home Ijara team, pre-approved property valuers, and a document checklist collected at application, so high-value customers are not lost to faster banks.

Sheet calc
A1: Status | B1: Deals | C1: Average Days | D1: Approved Amount | F1: Product | G1: Approved Amount | M1: KPI | N1: Value
A2: Approved | B2: 890 | C2: 6.7 | D2: 34751400 | F2: Home Ijara | G2: 15307100 | M2: Total Approved Amount | N2: =IFERROR(GETPIVOTDATA("Approved Amount",$A$1),0) -> 34751400
A3: Pending | B3: 54 | C3: #DIV/0! | D3: 0 | F3: SME Murabaha | G3: 10631400 | M3: Approved Deals | N3: =IFERROR(GETPIVOTDATA("Deals",$A$1,"Status","Approved"),0) -> 890
A4: Rejected | B4: 349 | C4: 9.4899713 | D4: 0 | F4: Personal Tawarruq | G4: 5322100 | M4: Approval Rate | N4: =IFERROR(GETPIVOTDATA("Approval %",$G$8,"Status","Approved"),0) -> 0.71832123
A5: Grand Total | B5: 1293 | C5: 7.4858757 | D5: 34751400 | F5: Auto Murabaha | G5: 3490800 | M5: Avg Approved Deal Size | N5: =IFERROR(N2/N3,0) -> 39046.517
F6: Grand Total | G6: 34751400 | M6: Avg Days to Decision | N6: =IFERROR(GETPIVOTDATA("Average Days",$A$1),0) -> 7.4858757
A7: Segment | B7: Approved Amount | D7: Months (ApplicationDate) | E7: Approved Amount
A8: Affluent | B8: 12355000 | D8: Jan | E8: 3763400 | G8: Approval % | H8: Status
A9: Mass | B9: 17448800 | D9: Feb | E9: 2617900 | G9: Channel | H9: Approved | I9: Rejected | J9: Grand Total
A10: Premium | B10: 4947600 | D10: Mar | E10: 5313100 | G10: Branch | H10: 0.74965229 | I10: 0.25034771 | J10: 1
A11: Grand Total | B11: 34751400 | D11: Apr | E11: 4301000 | G11: Mobile App | H11: 0.64497041 | I11: 0.35502959 | J11: 1
D12: May | E12: 3871700 | G12: Online | H12: 0.73076923 | I12: 0.26923077 | J12: 1
D13: Jun | E13: 3770000 | G13: Grand Total | H13: 0.71832123 | I13: 0.28167877 | J13: 1
D14: Jul | E14: 3863500
D15: Aug | E15: 4535100
D16: Sep | E16: 2715700
D17: Grand Total | E17: 34751400

Sheet Deals
A1: DealID | B1: ApplicationDate | C1: CustomerID | D1: Branch | E1: Product | F1: Channel | G1: Amount | H1: ProfitRate | I1: TenorMonths | J1: Officer | K1: Status | L1: DecisionDate | M1: Segment | N1: Nationality | O1: Age | P1: AgeGroup | Q1: DaysToDecision | R1: IsApproved | S1: ApprovedAmount | T1: ExpectedAnnualProfit
A2: FN-00005 | B2: 46023 | C2: C0473 | D2: Kuwait City | E2: Personal Tawarruq | F2: Branch | G2: 25000 | H2: 0.0583 | I2: 12 | J2: OFF-KUW-1 | K2: Approved | L2: 46030 | M2: =_xlfn.XLOOKUP(Deals[[#This Row],[CustomerID]],Customers!A:A,Customers!F:F) -> Affluent | N2: =_xlfn.XLOOKUP(Deals[[#This Row],[CustomerID]],Customers!A:A,Customers!E:E) -> Kuwaiti | O2: =2026-_xlfn.XLOOKUP(Deals[[#This Row],[CustomerID]],Customers!A:A,Customers!D:D) -> 53 | P2: {=_xlfn.IFS(Deals[[#This Row],[Age]]<30,"Under 30",Deals[[#This Row],[Age]]<45,"30-44",TRUE,"45+")} -> 45+ | Q2: =IF(Deals[[#This Row],[Status]]="Pending","",Deals[[#This Row],[DecisionDate]]-Deals[[#This Row],[ApplicationDate]]) -> 7 | R2: =IF(Deals[[#This Row],[Status]]="Approved",1,0) -> 1 | S2: =IF(Deals[[#This Row],[IsApproved]]=1,Deals[[#This Row],[Amount]],0) -> 25000 | T2: =Deals[[#This Row],[ApprovedAmount]]*Deals[[#This Row],[ProfitRate]] -> 1457.5
A3: FN-00013 | B3: 46023 | C3: C0939 | D3: Hawally | E3: Home Ijara | F3: Branch | G3: 122900 | H3: 0.0375 | I3: 120 | J3: OFF-HAW-3 | K3: Approved | L3: 46036 | M3: =_xlfn.XLOOKUP(Deals[[#This Row],[CustomerID]],Customers!A:A,Customers!F:F) -> Mass | N3: =_xlfn.XLOOKUP(Deals[[#This Row],[CustomerID]],Customers!A:A,Customers!E:E) -> Kuwaiti | O3: =2026-_xlfn.XLOOKUP(Deals[[#This Row],[CustomerID]],Customers!A:A,Customers!D:D) -> 23 | P3: {=_xlfn.IFS(Deals[[#This Row],[Age]]<30,"Under 30",Deals[[#This Row],[Age]]<45,"30-44",TRUE,"45+")} -> Under 30 | Q3: =IF(Deals[[#This Row],[Status]]="Pending","",Deals[[#This Row],[DecisionDate]]-Deals[[#This Row],[ApplicationDate]]) -> 13 | R3: =IF(Deals[[#This Row],[Status]]="Approved",1,0) -> 1 | S3: =IF(Deals[[#This Row],[IsApproved]]=1,Deals[[#This Row],[Amount]],0) -> 122900 | T3: =Deals[[#This Row],[ApprovedAmount]]*Deals[[#This Row],[ProfitRate]] -> 4608.75
A4: FN-00017 | B4: 46023 | C4: C0035 | D4: Salmiya | E4: Personal Tawarruq | F4: Branch | G4: 23200 | H4: 0.0682 | I4: 12 | J4: OFF-SAL-1 | K4: Approved | L4: 46030 | M4: =_xlfn.XLOOKUP(Deals[[#This Row],[CustomerID]],Customers!A:A,Customers!F:F) -> Affluent | N4: =_xlfn.XLOOKUP(Deals[[#This Row],[CustomerID]],Customers!A:A,Customers!E:E) -> Kuwaiti | O4: =2026-_xlfn.XLOOKUP(Deals[[#This Row],[CustomerID]],Customers!A:A,Customers!D:D) -> 25 | P4: {=_xlfn.IFS(Deals[[#This Row],[Age]]<30,"Under 30",Deals[[#This Row],[Age]]<45,"30-44",TRUE,"45+")} -> Under 30 | Q4: =IF(Deals[[#This Row],[Status]]="Pending","",Deals[[#This Row],[DecisionDate]]-Deals[[#This Row],[ApplicationDate]]) -> 7 | R4: =IF(Deals[[#This Row],[Status]]="Approved",1,0) -> 1 | S4: =IF(Deals[[#This Row],[IsApproved]]=1,Deals[[#This Row],[Amount]],0) -> 23200 | T4: =Deals[[#This Row],[ApprovedAmount]]*Deals[[#This Row],[ProfitRate]] -> 1582.24 | W4: Duplicates removed | 24
A5: FN-00019 | B5: 46023 | C5: C0228 | D5: Farwaniya | E5: Auto Murabaha | F5: Mobile App | G5: 11600 | H5: 0.0441 | I5: 48 | J5: OFF-FAR-2 | K5: Approved | L5: 46025 | M5: =_xlfn.XLOOKUP(Deals[[#This Row],[CustomerID]],Customers!A:A,Customers!F:F) -> Affluent | N5: =_xlfn.XLOOKUP(Deals[[#This Row],[CustomerID]],Customers!A:A,Customers!E:E) -> Kuwaiti | O5: =2026-_xlfn.XLOOKUP(Deals[[#This Row],[CustomerID]],Customers!A:A,Customers!D:D) -> 41 | P5: {=_xlfn.IFS(Deals[[#This Row],[Age]]<30,"Under 30",Deals[[#This Row],[Age]]<45,"30-44",TRUE,"45+")} -> 30-44 | Q5: =IF(Deals[[#This Row],[Status]]="Pending","",Deals[[#This Row],[DecisionDate]]-Deals[[#This Row],[ApplicationDate]]) -> 2 | R5: =IF(Deals[[#This Row],[Status]]="Approved",1,0) -> 1 | S5: =IF(Deals[[#This Row],[IsApproved]]=1,Deals[[#This Row],[Amount]],0) -> 11600 | T5: =Deals[[#This Row],[ApprovedAmount]]*Deals[[#This Row],[ProfitRate]] -> 511.56 | W5: Rejected Data|12
A6: FN-00048 | B6: 46023 | C6: C0904 | D6: Salmiya | E6: Personal Tawarruq | F6: Mobile App | G6: 24300 | H6: 0.0625 | I6: 60 | J6: OFF-SAL-1 | K6: Approved | L6: 46028 | M6: =_xlfn.XLOOKUP(Deals[[#This Row],[CustomerID]],Customers!A:A,Customers!F:F) -> Mass | N6: =_xlfn.XLOOKUP(Deals[[#This Row],[CustomerID]],Customers!A:A,Customers!E:E) -> Kuwaiti | O6: =2026-_xlfn.XLOOKUP(Deals[[#This Row],[CustomerID]],Customers!A:A,Customers!D:D) -> 25 | P6: {=_xlfn.IFS(Deals[[#This Row],[Age]]<30,"Under 30",Deals[[#This Row],[Age]]<45,"30-44",TRUE,"45+")} -> Under 30 | Q6: =IF(Deals[[#This Row],[Status]]="Pending","",Deals[[#This Row],[DecisionDate]]-Deals[[#This Row],[ApplicationDate]]) -> 5 | R6: =IF(Deals[[#This Row],[Status]]="Approved",1,0) -> 1 | S6: =IF(Deals[[#This Row],[IsApproved]]=1,Deals[[#This Row],[Amount]],0) -> 24300 | T6: =Deals[[#This Row],[ApprovedAmount]]*Deals[[#This Row],[ProfitRate]] -> 1518.75
A7: FN-00077 | B7: 46023 | C7: C0890 | D7: Hawally | E7: Personal Tawarruq | F7: Branch | G7: 10600 | H7: 0.06 | I7: 36 | J7: OFF-HAW-1 | K7: Approved | L7: 46025 | M7: =_xlfn.XLOOKUP(Deals[[#This Row],[CustomerID]],Customers!A:A,Customers!F:F) -> Mass | N7: =_xlfn.XLOOKUP(Deals[[#This Row],[CustomerID]],Customers!A:A,Customers!E:E) -> Kuwaiti | O7: =2026-_xlfn.XLOOKUP(Deals[[#This Row],[CustomerID]],Customers!A:A,Customers!D:D) -> 31 | P7: {=_xlfn.IFS(Deals[[#This Row],[Age]]<30,"Under 30",Deals[[#This Row],[Age]]<45,"30-44",TRUE,"45+")} -> 30-44 | Q7: =IF(Deals[[#This Row],[Status]]="Pending","",Deals[[#This Row],[DecisionDate]]-Deals[[#This Row],[ApplicationDate]]) -> 2 | R7: =IF(Deals[[#This Row],[Status]]="Approved",1,0) -> 1 | S7: =IF(Deals[[#This Row],[IsApproved]]=1,Deals[[#This Row],[Amount]],0) -> 10600 | T7: =Deals[[#This Row],[ApprovedAmount]]*Deals[[#This Row],[ProfitRate]] -> 636
A8: FN-00012 | B8: 46024 | C8: C0294 | D8: Kuwait City | E8: Personal Tawarruq | F8: Branch | G8: 20300 | H8: 0.0638 | I8: 12 | J8: OFF-KUW-2 | K8: Approved | L8: 46025 | M8: =_xlfn.XLOOKUP(Deals[[#This Row],[CustomerID]],Customers!A:A,Customers!F:F) -> Mass | N8: =_xlfn.XLOOKUP(Deals[[#This Row],[CustomerID]],Customers!A:A,Customers!E:E) -> Kuwaiti | O8: =2026-_xlfn.XLOOKUP(Deals[[#This Row],[CustomerID]],Customers!A:A,Customers!D:D) -> 26 | P8: {=_xlfn.IFS(Deals[[#This Row],[Age]]<30,"Under 30",Deals[[#This Row],[Age]]<45,"30-44",TRUE,"45+")} -> Under 30 | Q8: =IF(Deals[[#This Row],[Status]]="Pending","",Deals[[#This Row],[DecisionDate]]-Deals[[#This Row],[ApplicationDate]]) -> 1 | R8: =IF(Deals[[#This Row],[Status]]="Approved",1,0) -> 1 | S8: =IF(Deals[[#This Row],[IsApproved]]=1,Deals[[#This Row],[Amount]],0) -> 20300 | T8: =Deals[[#This Row],[ApprovedAmount]]*Deals[[#This Row],[ProfitRate]] -> 1295.14
A9: FN-00021 | B9: 46024 | C9: C0103 | D9: Hawally | E9: SME Murabaha | F9: Branch | G9: 55100 | H9: 0.076 | I9: 84 | J9: OFF-HAW-2 | K9: Rejected | L9: 46041 | M9: =_xlfn.XLOOKUP(Deals[[#This Row],[CustomerID]],Customers!A:A,Customers!F:F) -> Affluent | N9: =_xlfn.XLOOKUP(Deals[[#This Row],[CustomerID]],Customers!A:A,Customers!E:E) -> Kuwaiti | O9: =2026-_xlfn.XLOOKUP(Deals[[#This Row],[CustomerID]],Customers!A:A,Customers!D:D) -> 50 | P9: {=_xlfn.IFS(Deals[[#This Row],[Age]]<30,"Under 30",Deals[[#This Row],[Age]]<45,"30-44",TRUE,"45+")} -> 45+ | Q9: =IF(Deals[[#This Row],[Status]]="Pending","",Deals[[#This Row],[DecisionDate]]-Deals[[#This Row],[ApplicationDate]]) -> 17 | R9: =IF(Deals[[#This Row],[Status]]="Approved",1,0) -> 0 | S9: =IF(Deals[[#This Row],[IsApproved]]=1,Deals[[#This Row],[Amount]],0) -> 0 | T9: =Deals[[#This Row],[ApprovedAmount]]*Deals[[#This Row],[ProfitRate]] -> 0
A10: FN-00080 | B10: 46024 | C10: C0911 | D10: Kuwait City | E10: Personal Tawarruq | F10: Branch | G10: 2000 | H10: 0.0552 | I10: 24 | J10: OFF-KUW-3 | K10: Approved | L10: 46031 | M10: =_xlfn.XLOOKUP(Deals[[#This Row],[CustomerID]],Customers!A:A,Customers!F:F) -> Mass | N10: =_xlfn.XLOOKUP(Deals[[#This Row],[CustomerID]],Customers!A:A,Customers!E:E) -> Kuwaiti | O10: =2026-_xlfn.XLOOKUP(Deals[[#This Row],[CustomerID]],Customers!A:A,Customers!D:D) -> 50 | P10: {=_xlfn.IFS(Deals[[#This Row],[Age]]<30,"Under 30",Deals[[#This Row],[Age]]<45,"30-44",TRUE,"45+")} -> 45+ | Q10: =IF(Deals[[#This Row],[Status]]="Pending","",Deals[[#This Row],[DecisionDate]]-Deals[[#This Row],[ApplicationDate]]) -> 7 | R10: =IF(Deals[[#This Row],[Status]]="Approved",1,0) -> 1 | S10: =IF(Deals[[#This Row],[IsApproved]]=1,Deals[[#This Row],[Amount]],0) -> 2000 | T10: =Deals[[#This Row],[ApprovedAmount]]*Deals[[#This Row],[ProfitRate]] -> 110.4
A11: FN-00094 | B11: 46024 | C11: C0641 | D11: Hawally | E11: Auto Murabaha | F11: Mobile App | G11: 10600 | H11: 0.0472 | I11: 36 | J11: OFF-HAW-1 | K11: Approved | L11: 46028 | M11: =_xlfn.XLOOKUP(Deals[[#This Row],[CustomerID]],Customers!A:A,Customers!F:F) -> Affluent | N11: =_xlfn.XLOOKUP(Deals[[#This Row],[CustomerID]],Customers!A:A,Customers!E:E) -> Kuwaiti | O11: =2026-_xlfn.XLOOKUP(Deals[[#This Row],[CustomerID]],Customers!A:A,Customers!D:D) -> 45 | P11: {=_xlfn.IFS(Deals[[#This Row],[Age]]<30,"Under 30",Deals[[#This Row],[Age]]<45,"30-44",TRUE,"45+")} -> 45+ | Q11: =IF(Deals[[#This Row],[Status]]="Pending","",Deals[[#This Row],[DecisionDate]]-Deals[[#This Row],[ApplicationDate]]) -> 4 | R11: =IF(Deals[[#This Row],[Status]]="Approved",1,0) -> 1 | S11: =IF(Deals[[#This Row],[IsApproved]]=1,Deals[[#This Row],[Amount]],0) -> 10600 | T11: =Deals[[#This Row],[ApprovedAmount]]*Deals[[#This Row],[ProfitRate]] -> 500.32
A12: FN-00032 | B12: 46025 | C12: C0405 | D12: Ahmadi | E12: Auto Murabaha | F12: Online | G12: 9600 | H12: 0.042 | I12: 36 | J12: OFF-AHM-1 | K12: Approved | L12: 46029 | M12: =_xlfn.XLOOKUP(Deals[[#This Row],[CustomerID]],Customers!A:A,Customers!F:F) -> Premium | N12: =_xlfn.XLOOKUP(Deals[[#This Row],[CustomerID]],Customers!A:A,Customers!E:E) -> Kuwaiti | O12: =2026-_xlfn.XLOOKUP(Deals[[#This Row],[CustomerID]],Customers!A:A,Customers!D:D) -> 23 | P12: {=_xlfn.IFS(Deals[[#This Row],[Age]]<30,"Under 30",Deals[[#This Row],[Age]]<45,"30-44",TRUE,"45+")} -> Under 30 | Q12: =IF(Deals[[#This Row],[Status]]="Pending","",Deals[[#This Row],[DecisionDate]]-Deals[[#This Row],[ApplicationDate]]) -> 4 | R12: =IF(Deals[[#This Row],[Status]]="Approved",1,0) -> 1 | S12: =IF(Deals[[#This Row],[IsApproved]]=1,Deals[[#This Row],[Amount]],0) -> 9600 | T12: =Deals[[#This Row],[ApprovedAmount]]*Deals[[#This Row],[ProfitRate]] -> 403.2
A13: FN-00063 | B13: 46025 | C13: C0884 | D13: Hawally | E13: Personal Tawarruq | F13: Branch | G13: 12700 | H13: 0.0546 | I13: 24 | J13: OFF-HAW-3 | K13: Approved | L13: 46031 | M13: =_xlfn.XLOOKUP(Deals[[#This Row],[CustomerID]],Customers!A:A,Customers!F:F) -> Affluent | N13: =_xlfn.XLOOKUP(Deals[[#This Row],[CustomerID]],Customers!A:A,Customers!E:E) -> Kuwaiti | O13: =2026-_xlfn.XLOOKUP(Deals[[#This Row],[CustomerID]],Customers!A:A,Customers!D:D) -> 64 | P13: {=_xlfn.IFS(Deals[[#This Row],[Age]]<30,"Under 30",Deals[[#This Row],[Age]]<45,"30-44",TRUE,"45+")} -> 45+ | Q13: =IF(Deals[[#This Row],[Status]]="Pending","",Deals[[#This Row],[DecisionDate]]-Deals[[#This Row],[ApplicationDate]]) -> 6 | R13: =IF(Deals[[#This Row],[Status]]="Approved",1,0) -> 1 | S13: =IF(Deals[[#This Row],[IsApproved]]=1,Deals[[#This Row],[Amount]],0) -> 12700 | T13: =Deals[[#This Row],[ApprovedAmount]]*Deals[[#This Row],[ProfitRate]] -> 693.42
A14: FN-00107 | B14: 46025 | C14: C0332 | D14: Farwaniya | E14: Personal Tawarruq | F14: Branch | G14: 12300 | H14: 0.0618 | I14: 60 | J14: OFF-FAR-1 | K14: Approved | L14: 46027 | M14: =_xlfn.XLOOKUP(Deals[[#This Row],[CustomerID]],Customers!A:A,Customers!F:F) -> Mass | N14: =_xlfn.XLOOKUP(Deals[[#This Row],[CustomerID]],Customers!A:A,Customers!E:E) -> Non-Kuwaiti | O14: =2026-_xlfn.XLOOKUP(Deals[[#This Row],[CustomerID]],Customers!A:A,Customers!D:D) -> 43 | P14: {=_xlfn.IFS(Deals[[#This Row],[Age]]<30,"Under 30",Deals[[#This Row],[Age]]<45,"30-44",TRUE,"45+")} -> 30-44 | Q14: =IF(Deals[[#This Row],[Status]]="Pending","",Deals[[#This Row],[DecisionDate]]-Deals[[#This Row],[ApplicationDate]]) -> 2 | R14: =IF(Deals[[#This Row],[Status]]="Approved",1,0) -> 1 | S14: =IF(Deals[[#This Row],[IsApproved]]=1,Deals[[#This Row],[Amount]],0) -> 12300 | T14: =Deals[[#This Row],[ApprovedAmount]]*Deals[[#This Row],[ProfitRate]] -> 760.14
A15: FN-00043 | B15: 46026 | C15: C0874 | D15: Hawally | E15: SME Murabaha | F15: Mobile App | G15: 110700 | H15: 0.0792 | I15: 84 | J15: OFF-HAW-3 | K15: Rejected | L15: 46041 | M15: =_xlfn.XLOOKUP(Deals[[#This Row],[CustomerID]],Customers!A:A,Customers!F:F) -> Mass | N15: =_xlfn.XLOOKUP(Deals[[#This Row],[CustomerID]],Customers!A:A,Customers!E:E) -> Kuwaiti | O15: =2026-_xlfn.XLOOKUP(Deals[[#This Row],[CustomerID]],Customers!A:A,Customers!D:D) -> 35 | P15: {=_xlfn.IFS(Deals[[#This Row],[Age]]<30,"Under 30",Deals[[#This Row],[Age]]<45,"30-44",TRUE,"45+")} -> 30-44 | Q15: =IF(Deals[[#This Row],[Status]]="Pending","",Deals[[#This Row],[DecisionDate]]-Deals[[#This Row],[ApplicationDate]]) -> 15 | R15: =IF(Deals[[#This Row],[Status]]="Approved",1,0) -> 0 | S15: =IF(Deals[[#This Row],[IsApproved]]=1,Deals[[#This Row],[Amount]],0) -> 0 | T15: =Deals[[#This Row],[ApprovedAmount]]*Deals[[#This Row],[ProfitRate]] -> 0
A16: FN-00047 | B16: 46026 | C16: C0780 | D16: Salmiya | E16: Auto Murabaha | F16: Branch | G16: 7400 | H16: 0.0385 | I16: 60 | J16: OFF-SAL-3 | K16: Rejected | L16: 46030 | M16: =_xlfn.XLOOKUP(Deals[[#This Row],[CustomerID]],Customers!A:A,Customers!F:F) -> Mass | N16: =_xlfn.XLOOKUP(Deals[[#This Row],[CustomerID]],Customers!A:A,Customers!E:E) -> Non-Kuwaiti | O16: =2026-_xlfn.XLOOKUP(Deals[[#This Row],[CustomerID]],Customers!A:A,Customers!D:D) -> 25 | P16: {=_xlfn.IFS(Deals[[#This Row],[Age]]<30,"Under 30",Deals[[#This Row],[Age]]<45,"30-44",TRUE,"45+")} -> Under 30 | Q16: =IF(Deals[[#This Row],[Status]]="Pending","",Deals[[#This Row],[DecisionDate]]-Deals[[#This Row],[ApplicationDate]]) -> 4 | R16: =IF(Deals[[#This Row],[Status]]="Approved",1,0) -> 0 | S16: =IF(Deals[[#This Row],[IsApproved]]=1,Deals[[#This Row],[Amount]],0) -> 0 | T16: =Deals[[#This Row],[ApprovedAmount]]*Deals[[#This Row],[ProfitRate]] -> 0
A17: FN-00086 | B17: 46026 | C17: C0438 | D17: Hawally | E17: Personal Tawarruq | F17: Branch | G17: 12300 | H17: 0.0561 | I17: 12 | J17: OFF-HAW-2 | K17: Approved | L17: 46033 | M17: =_xlfn.XLOOKUP(Deals[[#This Row],[CustomerID]],Customers!A:A,Customers!F:F) -> Mass | N17: =_xlfn.XLOOKUP(Deals[[#This Row],[CustomerID]],Customers!A:A,Customers!E:E) -> Non-Kuwaiti | O17: =2026-_xlfn.XLOOKUP(Deals[[#This Row],[CustomerID]],Customers!A:A,Customers!D:D) -> 33 | P17: {=_xlfn.IFS(Deals[[#This Row],[Age]]<30,"Under 30",Deals[[#This Row],[Age]]<45,"30-44",TRUE,"45+")} -> 30-44 | Q17: =IF(Deals[[#This Row],[Status]]="Pending","",Deals[[#This Row],[DecisionDate]]-Deals[[#This Row],[ApplicationDate]]) -> 7 | R17: =IF(Deals[[#This Row],[Status]]="Approved",1,0) -> 1 | S17: =IF(Deals[[#This Row],[IsApproved]]=1,Deals[[#This Row],[Amount]],0) -> 12300 | T17: =Deals[[#This Row],[ApprovedAmount]]*Deals[[#This Row],[ProfitRate]] -> 690.03
... A1148: FN-01167 | B1148: 46266 | C1148: C0571 | D1148: Hawally | E1148: Home Ijara | F1148: Online | G1148: 50000 | H1148: 0.043 | I1148: 180 | J1148: OFF-HAW-2 | K1148: Approved | L1148: 46282 | M1148: =_xlfn.XLOOKUP(Deals[[#This Row],[CustomerID]],Customers!A:A,Customers!F:F) -> Mass | N1148: =_xlfn.XLOOKUP(Deals[[#This Row],[CustomerID]],Customers!A:A,Customers!E:E) -> Non-Kuwaiti | O1148: =2026-_xlfn.XLOOKUP(Deals[[#This Row],[CustomerID]],Customers!A:A,Customers!D:D) -> 69 | P1148: {=_xlfn.IFS(Deals[[#This Row],[Age]]<30,"Under 30",Deals[[#This Row],[Age]]<45,"30-44",TRUE,"45+")} -> 45+ | Q1148: =IF(Deals[[#This Row],[Status]]="Pending","",Deals[[#This Row],[DecisionDate]]-Deals[[#This Row],[ApplicationDate]]) -> 16 | R1148: =IF(Deals[[#This Row],[Status]]="Approved",1,0) -> 1 | S1148: =IF(Deals[[#This Row],[IsApproved]]=1,Deals[[#This Row],[Amount]],0) -> 50000 | T1148: =Deals[[#This Row],[ApprovedAmount]]*Deals[[#This Row],[ProfitRate]] -> 2150
A1149: FN-01168 | B1149: 46266 | C1149: C0588 | D1149: Salmiya | E1149: Personal Tawarruq | F1149: Mobile App | G1149: 17600 | H1149: 0.0568 | I1149: 12 | J1149: OFF-SAL-3 | K1149: Pending | M1149: =_xlfn.XLOOKUP(Deals[[#This Row],[CustomerID]],Customers!A:A,Customers!F:F) -> Affluent | N1149: =_xlfn.XLOOKUP(Deals[[#This Row],[CustomerID]],Customers!A:A,Customers!E:E) -> Kuwaiti | O1149: =2026-_xlfn.XLOOKUP(Deals[[#This Row],[CustomerID]],Customers!A:A,Customers!D:D) -> 23 | P1149: {=_xlfn.IFS(Deals[[#This Row],[Age]]<30,"Under 30",Deals[[#This Row],[Age]]<45,"30-44",TRUE,"45+")} -> Under 30 | Q1149: =IF(Deals[[#This Row],[Status]]="Pending","",Deals[[#This Row],[DecisionDate]]-Deals[[#This Row],[ApplicationDate]]) | R1149: =IF(Deals[[#This Row],[Status]]="Approved",1,0) -> 0 | S1149: =IF(Deals[[#This Row],[IsApproved]]=1,Deals[[#This Row],[Amount]],0) -> 0 | T1149: =Deals[[#This Row],[ApprovedAmount]]*Deals[[#This Row],[ProfitRate]] -> 0
A1150: FN-01192 | B1150: 46266 | C1150: C0854 | D1150: Hawally | E1150: Home Ijara | F1150: Mobile App | G1150: 246200 | H1150: 0.0332 | I1150: 120 | J1150: OFF-HAW-3 | K1150: Approved | L1150: 46293 | M1150: =_xlfn.XLOOKUP(Deals[[#This Row],[CustomerID]],Customers!A:A,Customers!F:F) -> Mass | N1150: =_xlfn.XLOOKUP(Deals[[#This Row],[CustomerID]],Customers!A:A,Customers!E:E) -> Kuwaiti | O1150: =2026-_xlfn.XLOOKUP(Deals[[#This Row],[CustomerID]],Customers!A:A,Customers!D:D) -> 23 | P1150: {=_xlfn.IFS(Deals[[#This Row],[Age]]<30,"Under 30",Deals[[#This Row],[Age]]<45,"30-44",TRUE,"45+")} -> Under 30 | Q1150: =IF(Deals[[#This Row],[Status]]="Pending","",Deals[[#This Row],[DecisionDate]]-Deals[[#This Row],[ApplicationDate]]) -> 27 | R1150: =IF(Deals[[#This Row],[Status]]="Approved",1,0) -> 1 | S1150: =IF(Deals[[#This Row],[IsApproved]]=1,Deals[[#This Row],[Amount]],0) -> 246200 | T1150: =Deals[[#This Row],[ApprovedAmount]]*Deals[[#This Row],[ProfitRate]] -> 8173.84
A1151: FN-01219 | B1151: 46266 | C1151: C0550 | D1151: Ahmadi | E1151: Auto Murabaha | F1151: Mobile App | G1151: 17400 | H1151: 0.043 | I1151: 36 | J1151: OFF-AHM-1 | K1151: Approved | L1151: 46269 | M1151: =_xlfn.XLOOKUP(Deals[[#This Row],[CustomerID]],Customers!A:A,Customers!F:F) -> Premium | N1151: =_xlfn.XLOOKUP(Deals[[#This Row],[CustomerID]],Customers!A:A,Customers!E:E) -> Non-Kuwaiti | O1151: =2026-_xlfn.XLOOKUP(Deals[[#This Row],[CustomerID]],Customers!A:A,Customers!D:D) -> 58 | P1151: {=_xlfn.IFS(Deals[[#This Row],[Age]]<30,"Under 30",Deals[[#This Row],[Age]]<45,"30-44",TRUE,"45+")} -> 45+ | Q1151: =IF(Deals[[#This Row],[Status]]="Pending","",Deals[[#This Row],[DecisionDate]]-Deals[[#This Row],[ApplicationDate]]) -> 3 | R1151: =IF(Deals[[#This Row],[Status]]="Approved",1,0) -> 1 | S1151: =IF(Deals[[#This Row],[IsApproved]]=1,Deals[[#This Row],[Amount]],0) -> 17400 | T1151: =Deals[[#This Row],[ApprovedAmount]]*Deals[[#This Row],[ProfitRate]] -> 748.2
A1152: FN-01225 | B1152: 46266 | C1152: C0046 | D1152: Farwaniya | E1152: Home Ijara | F1152: Mobile App | G1152: 190000 | H1152: 0.039 | I1152: 300 | J1152: OFF-FAR-2 | K1152: Rejected | L1152: 46283 | M1152: =_xlfn.XLOOKUP(Deals[[#This Row],[CustomerID]],Customers!A:A,Customers!F:F) -> Mass | N1152: =_xlfn.XLOOKUP(Deals[[#This Row],[CustomerID]],Customers!A:A,Customers!E:E) -> Non-Kuwaiti | O1152: =2026-_xlfn.XLOOKUP(Deals[[#This Row],[CustomerID]],Customers!A:A,Customers!D:D) -> 63 | P1152: {=_xlfn.IFS(Deals[[#This Row],[Age]]<30,"Under 30",Deals[[#This Row],[Age]]<45,"30-44",TRUE,"45+")} -> 45+ | Q1152: =IF(Deals[[#This Row],[Status]]="Pending","",Deals[[#This Row],[DecisionDate]]-Deals[[#This Row],[ApplicationDate]]) -> 17 | R1152: =IF(Deals[[#This Row],[Status]]="Approved",1,0) -> 0 | S1152: =IF(Deals[[#This Row],[IsApproved]]=1,Deals[[#This Row],[Amount]],0) -> 0 | T1152: =Deals[[#This Row],[ApprovedAmount]]*Deals[[#This Row],[ProfitRate]] -> 0
A1153: FN-01245 | B1153: 46266 | C1153: C0551 | D1153: Hawally | E1153: SME Murabaha | F1153: Branch | G1153: 75400 | H1153: 0.0551 | I1153: 84 | J1153: OFF-HAW-2 | K1153: Approved | L1153: 46282 | M1153: =_xlfn.XLOOKUP(Deals[[#This Row],[CustomerID]],Customers!A:A,Customers!F:F) -> Mass | N1153: =_xlfn.XLOOKUP(Deals[[#This Row],[CustomerID]],Customers!A:A,Customers!E:E) -> Non-Kuwaiti | O1153: =2026-_xlfn.XLOOKUP(Deals[[#This Row],[CustomerID]],Customers!A:A,Customers!D:D) -> 25 | P1153: {=_xlfn.IFS(Deals[[#This Row],[Age]]<30,"Under 30",Deals[[#This Row],[Age]]<45,"30-44",TRUE,"45+")} -> Under 30 | Q1153: =IF(Deals[[#This Row],[Status]]="Pending","",Deals[[#This Row],[DecisionDate]]-Deals[[#This Row],[ApplicationDate]]) -> 16 | R1153: =IF(Deals[[#This Row],[Status]]="Approved",1,0) -> 1 | S1153: =IF(Deals[[#This Row],[IsApproved]]=1,Deals[[#This Row],[Amount]],0) -> 75400 | T1153: =Deals[[#This Row],[ApprovedAmount]]*Deals[[#This Row],[ProfitRate]] -> 4154.54
A1154: FN-01266 | B1154: 46266 | C1154: C0631 | D1154: Kuwait City | E1154: Personal Tawarruq | F1154: Mobile App | G1154: 11000 | H1154: 0.0673 | I1154: 24 | J1154: OFF-KUW-2 | K1154: Approved | L1154: 46267 | M1154: =_xlfn.XLOOKUP(Deals[[#This Row],[CustomerID]],Customers!A:A,Customers!F:F) -> Mass | N1154: =_xlfn.XLOOKUP(Deals[[#This Row],[CustomerID]],Customers!A:A,Customers!E:E) -> Kuwaiti | O1154: =2026-_xlfn.XLOOKUP(Deals[[#This Row],[CustomerID]],Customers!A:A,Customers!D:D) -> 38 | P1154: {=_xlfn.IFS(Deals[[#This Row],[Age]]<30,"Under 30",Deals[[#This Row],[Age]]<45,"30-44",TRUE,"45+")} -> 30-44 | Q1154: =IF(Deals[[#This Row],[Status]]="Pending","",Deals[[#This Row],[DecisionDate]]-Deals[[#This Row],[ApplicationDate]]) -> 1 | R1154: =IF(Deals[[#This Row],[Status]]="Approved",1,0) -> 1 | S1154: =IF(Deals[[#This Row],[IsApproved]]=1,Deals[[#This Row],[Amount]],0) -> 11000 | T1154: =Deals[[#This Row],[ApprovedAmount]]*Deals[[#This Row],[ProfitRate]] -> 740.3
A1155: FN-01196 | B1155: 46267 | C1155: C0680 | D1155: Ahmadi | E1155: Home Ijara | F1155: Mobile App | G1155: 182300 | H1155: 0.0449 | I1155: 300 | J1155: OFF-AHM-1 | K1155: Rejected | L1155: 46276 | M1155: =_xlfn.XLOOKUP(Deals[[#This Row],[CustomerID]],Customers!A:A,Customers!F:F) -> Mass | N1155: =_xlfn.XLOOKUP(Deals[[#This Row],[CustomerID]],Customers!A:A,Customers!E:E) -> Non-Kuwaiti | O1155: =2026-_xlfn.XLOOKUP(Deals[[#This Row],[CustomerID]],Customers!A:A,Customers!D:D) -> 46 | P1155: {=_xlfn.IFS(Deals[[#This Row],[Age]]<30,"Under 30",Deals[[#This Row],[Age]]<45,"30-44",TRUE,"45+")} -> 45+ | Q1155: =IF(Deals[[#This Row],[Status]]="Pending","",Deals[[#This Row],[DecisionDate]]-Deals[[#This Row],[ApplicationDate]]) -> 9 | R1155: =IF(Deals[[#This Row],[Status]]="Approved",1,0) -> 0 | S1155: =IF(Deals[[#This Row],[IsApproved]]=1,Deals[[#This Row],[Amount]],0) -> 0 | T1155: =Deals[[#This Row],[ApprovedAmount]]*Deals[[#This Row],[ProfitRate]] -> 0
A1156: FN-01197 | B1156: 46267 | C1156: C0559 | D1156: Farwaniya | E1156: SME Murabaha | F1156: Online | G1156: 61100 | H1156: 0.0723 | I1156: 60 | J1156: OFF-FAR-3 | K1156: Rejected | L1156: 46281 | M1156: =_xlfn.XLOOKUP(Deals[[#This Row],[CustomerID]],Customers!A:A,Customers!F:F) -> Mass | N1156: =_xlfn.XLOOKUP(Deals[[#This Row],[CustomerID]],Customers!A:A,Customers!E:E) -> Kuwaiti | O1156: =2026-_xlfn.XLOOKUP(Deals[[#This Row],[CustomerID]],Customers!A:A,Customers!D:D) -> 26 | P1156: {=_xlfn.IFS(Deals[[#This Row],[Age]]<30,"Under 30",Deals[[#This Row],[Age]]<45,"30-44",TRUE,"45+")} -> Under 30 | Q1156: =IF(Deals[[#This Row],[Status]]="Pending","",Deals[[#This Row],[DecisionDate]]-Deals[[#This Row],[ApplicationDate]]) -> 14 | R1156: =IF(Deals[[#This Row],[Status]]="Approved",1,0) -> 0 | S1156: =IF(Deals[[#This Row],[IsApproved]]=1,Deals[[#This Row],[Amount]],0) -> 0 | T1156: =Deals[[#This Row],[ApprovedAmount]]*Deals[[#This Row],[ProfitRate]] -> 0
A1157: FN-01280 | B1157: 46267 | C1157: C0169 | D1157: Farwaniya | E1157: Personal Tawarruq | F1157: Online | G1157: 23900 | H1157: 0.0584 | I1157: 12 | J1157: OFF-FAR-2 | K1157: Approved | L1157: 46274 | M1157: =_xlfn.XLOOKUP(Deals[[#This Row],[CustomerID]],Customers!A:A,Customers!F:F) -> Mass | N1157: =_xlfn.XLOOKUP(Deals[[#This Row],[CustomerID]],Customers!A:A,Customers!E:E) -> Kuwaiti | O1157: =2026-_xlfn.XLOOKUP(Deals[[#This Row],[CustomerID]],Customers!A:A,Customers!D:D) -> 68 | P1157: {=_xlfn.IFS(Deals[[#This Row],[Age]]<30,"Under 30",Deals[[#This Row],[Age]]<45,"30-44",TRUE,"45+")} -> 45+ | Q1157: =IF(Deals[[#This Row],[Status]]="Pending","",Deals[[#This Row],[DecisionDate]]-Deals[[#This Row],[ApplicationDate]]) -> 7 | R1157: =IF(Deals[[#This Row],[Status]]="Approved",1,0) -> 1 | S1157: =IF(Deals[[#This Row],[IsApproved]]=1,Deals[[#This Row],[Amount]],0) -> 23900 | T1157: =Deals[[#This Row],[ApprovedAmount]]*Deals[[#This Row],[ProfitRate]] -> 1395.76
A1158: FN-01207 | B1158: 46268 | C1158: C0707 | D1158: Salmiya | E1158: Auto Murabaha | F1158: Branch | G1158: 4800 | H1158: 0.0377 | I1158: 60 | J1158: OFF-SAL-3 | K1158: Approved | L1158: 46273 | M1158: =_xlfn.XLOOKUP(Deals[[#This Row],[CustomerID]],Customers!A:A,Customers!F:F) -> Mass | N1158: =_xlfn.XLOOKUP(Deals[[#This Row],[CustomerID]],Customers!A:A,Customers!E:E) -> Non-Kuwaiti | O1158: =2026-_xlfn.XLOOKUP(Deals[[#This Row],[CustomerID]],Customers!A:A,Customers!D:D) -> 40 | P1158: {=_xlfn.IFS(Deals[[#This Row],[Age]]<30,"Under 30",Deals[[#This Row],[Age]]<45,"30-44",TRUE,"45+")} -> 30-44 | Q1158: =IF(Deals[[#This Row],[Status]]="Pending","",Deals[[#This Row],[DecisionDate]]-Deals[[#This Row],[ApplicationDate]]) -> 5 | R1158: =IF(Deals[[#This Row],[Status]]="Approved",1,0) -> 1 | S1158: =IF(Deals[[#This Row],[IsApproved]]=1,Deals[[#This Row],[Amount]],0) -> 4800 | T1158: =Deals[[#This Row],[ApprovedAmount]]*Deals[[#This Row],[ProfitRate]] -> 180.96
A1159: FN-01220 | B1159: 46268 | C1159: C0904 | D1159: Kuwait City | E1159: SME Murabaha | F1159: Branch | G1159: 52000 | H1159: 0.0701 | I1159: 60 | J1159: OFF-KUW-2 | K1159: Approved | L1159: 46288 | M1159: =_xlfn.XLOOKUP(Deals[[#This Row],[CustomerID]],Customers!A:A,Customers!F:F) -> Mass | N1159: =_xlfn.XLOOKUP(Deals[[#This Row],[CustomerID]],Customers!A:A,Customers!E:E) -> Kuwaiti | O1159: =2026-_xlfn.XLOOKUP(Deals[[#This Row],[CustomerID]],Customers!A:A,Customers!D:D) -> 25 | P1159: {=_xlfn.IFS(Deals[[#This Row],[Age]]<30,"Under 30",Deals[[#This Row],[Age]]<45,"30-44",TRUE,"45+")} -> Under 30 | Q1159: =IF(Deals[[#This Row],[Status]]="Pending","",Deals[[#This Row],[DecisionDate]]-Deals[[#This Row],[ApplicationDate]]) -> 20 | R1159: =IF(Deals[[#This Row],[Status]]="Approved",1,0) -> 1 | S1159: =IF(Deals[[#This Row],[IsApproved]]=1,Deals[[#This Row],[Amount]],0) -> 52000 | T1159: =Deals[[#This Row],[ApprovedAmount]]*Deals[[#This Row],[ProfitRate]] -> 3645.2
A1160: FN-01228 | B1160: 46268 | C1160: C0628 | D1160: Salmiya | E1160: Personal Tawarruq | F1160: Branch | G1160: 11700 | H1160: 0.0542 | I1160: 36 | J1160: OFF-SAL-3 | K1160: Approved | L1160: 46270 | M1160: =_xlfn.XLOOKUP(Deals[[#This Row],[CustomerID]],Customers!A:A,Customers!F:F) -> Premium | N1160: =_xlfn.XLOOKUP(Deals[[#This Row],[CustomerID]],Customers!A:A,Customers!E:E) -> Kuwaiti | O1160: =2026-_xlfn.XLOOKUP(Deals[[#This Row],[CustomerID]],Customers!A:A,Customers!D:D) -> 38 | P1160: {=_xlfn.IFS(Deals[[#This Row],[Age]]<30,"Under 30",Deals[[#This Row],[Age]]<45,"30-44",TRUE,"45+")} -> 30-44 | Q1160: =IF(Deals[[#This Row],[Status]]="Pending","",Deals[[#This Row],[DecisionDate]]-Deals[[#This Row],[ApplicationDate]]) -> 2 | R1160: =IF(Deals[[#This Row],[Status]]="Approved",1,0) -> 1 | S1160: =IF(Deals[[#This Row],[IsApproved]]=1,Deals[[#This Row],[Amount]],0) -> 11700 | T1160: =Deals[[#This Row],[ApprovedAmount]]*Deals[[#This Row],[ProfitRate]] -> 634.14
A1161: FN-01287 | B1161: 46268 | C1161: C0238 | D1161: Farwaniya | E1161: Auto Murabaha | F1161: Mobile App | G1161: 13900 | H1161: 0.0486 | I1161: 36 | J1161: OFF-FAR-2 | K1161: Rejected | L1161: 46270 | M1161: =_xlfn.XLOOKUP(Deals[[#This Row],[CustomerID]],Customers!A:A,Customers!F:F) -> Mass | N1161: =_xlfn.XLOOKUP(Deals[[#This Row],[CustomerID]],Customers!A:A,Customers!E:E) -> Kuwaiti | O1161: =2026-_xlfn.XLOOKUP(Deals[[#This Row],[CustomerID]],Customers!A:A,Customers!D:D) -> 49 | P1161: {=_xlfn.IFS(Deals[[#This Row],[Age]]<30,"Under 30",Deals[[#This Row],[Age]]<45,"30-44",TRUE,"45+")} -> 45+ | Q1161: =IF(Deals[[#This Row],[Status]]="Pending","",Deals[[#This Row],[DecisionDate]]-Deals[[#This Row],[ApplicationDate]]) -> 2 | R1161: =IF(Deals[[#This Row],[Status]]="Approved",1,0) -> 0 | S1161: =IF(Deals[[#This Row],[IsApproved]]=1,Deals[[#This Row],[Amount]],0) -> 0 | T1161: =Deals[[#This Row],[ApprovedAmount]]*Deals[[#This Row],[ProfitRate]] -> 0
... A1167: FN-01210 | B1167: 46270 | C1167: C0356 | D1167: Kuwait City | E1167: Personal Tawarruq | F1167: Mobile App | G1167: 19400 | H1167: 0.067 | I1167: 60 | J1167: OFF-KUW-1 | K1167: Rejected | L1167: 46276 | M1167: =_xlfn.XLOOKUP(Deals[[#This Row],[CustomerID]],Customers!A:A,Customers!F:F) -> Affluent | N1167: =_xlfn.XLOOKUP(Deals[[#This Row],[CustomerID]],Customers!A:A,Customers!E:E) -> Kuwaiti | O1167: =2026-_xlfn.XLOOKUP(Deals[[#This Row],[CustomerID]],Customers!A:A,Customers!D:D) -> 38 | P1167: {=_xlfn.IFS(Deals[[#This Row],[Age]]<30,"Under 30",Deals[[#This Row],[Age]]<45,"30-44",TRUE,"45+")} -> 30-44 | Q1167: =IF(Deals[[#This Row],[Status]]="Pending","",Deals[[#This Row],[DecisionDate]]-Deals[[#This Row],[ApplicationDate]]) -> 6 | R1167: =IF(Deals[[#This Row],[Status]]="Approved",1,0) -> 0 | S1167: =IF(Deals[[#This Row],[IsApproved]]=1,Deals[[#This Row],[Amount]],0) -> 0 | T1167: =Deals[[#This Row],[ApprovedAmount]]*Deals[[#This Row],[ProfitRate]] -> 0
A1168: FN-01211 | B1168: 46270 | C1168: C0207 | D1168: Kuwait City | E1168: Auto Murabaha | F1168: Online | G1168: 15100 | H1168: 0.0494 | I1168: 60 | J1168: OFF-KUW-1 | K1168: Pending | M1168: =_xlfn.XLOOKUP(Deals[[#This Row],[CustomerID]],Customers!A:A,Customers!F:F) -> Affluent | N1168: =_xlfn.XLOOKUP(Deals[[#This Row],[CustomerID]],Customers!A:A,Customers!E:E) -> Kuwaiti | O1168: =2026-_xlfn.XLOOKUP(Deals[[#This Row],[CustomerID]],Customers!A:A,Customers!D:D) -> 58 | P1168: {=_xlfn.IFS(Deals[[#This Row],[Age]]<30,"Under 30",Deals[[#This Row],[Age]]<45,"30-44",TRUE,"45+")} -> 45+ | Q1168: =IF(Deals[[#This Row],[Status]]="Pending","",Deals[[#This Row],[DecisionDate]]-Deals[[#This Row],[ApplicationDate]]) | R1168: =IF(Deals[[#This Row],[Status]]="Approved",1,0) -> 0 | S1168: =IF(Deals[[#This Row],[IsApproved]]=1,Deals[[#This Row],[Amount]],0) -> 0 | T1168: =Deals[[#This Row],[ApprovedAmount]]*Deals[[#This Row],[ProfitRate]] -> 0
A1169: FN-01302 | B1169: 46270 | C1169: C0921 | D1169: Farwaniya | E1169: Personal Tawarruq | F1169: Branch | G1169: 13700 | H1169: 0.0615 | I1169: 60 | J1169: OFF-FAR-2 | K1169: Approved | L1169: 46271 | M1169: =_xlfn.XLOOKUP(Deals[[#This Row],[CustomerID]],Customers!A:A,Customers!F:F) -> Affluent | N1169: =_xlfn.XLOOKUP(Deals[[#This Row],[CustomerID]],Customers!A:A,Customers!E:E) -> Kuwaiti | O1169: =2026-_xlfn.XLOOKUP(Deals[[#This Row],[CustomerID]],Customers!A:A,Customers!D:D) -> 43 | P1169: {=_xlfn.IFS(Deals[[#This Row],[Age]]<30,"Under 30",Deals[[#This Row],[Age]]<45,"30-44",TRUE,"45+")} -> 30-44 | Q1169: =IF(Deals[[#This Row],[Status]]="Pending","",Deals[[#This Row],[DecisionDate]]-Deals[[#This Row],[ApplicationDate]]) -> 1 | R1169: =IF(Deals[[#This Row],[Status]]="Approved",1,0) -> 1 | S1169: =IF(Deals[[#This Row],[IsApproved]]=1,Deals[[#This Row],[Amount]],0) -> 13700 | T1169: =Deals[[#This Row],[ApprovedAmount]]*Deals[[#This Row],[ProfitRate]] -> 842.55
A1170: FN-01161 | B1170: 46271 | C1170: C0271 | D1170: Jahra | E1170: Home Ijara | F1170: Mobile App | G1170: 174500 | H1170: 0.0396 | I1170: 180 | J1170: OFF-JAH-1 | K1170: Rejected | L1170: 46296 | M1170: =_xlfn.XLOOKUP(Deals[[#This Row],[CustomerID]],Customers!A:A,Customers!F:F) -> Mass | N1170: =_xlfn.XLOOKUP(Deals[[#This Row],[CustomerID]],Customers!A:A,Customers!E:E) -> Kuwaiti | O1170: =2026-_xlfn.XLOOKUP(Deals[[#This Row],[CustomerID]],Customers!A:A,Customers!D:D) -> 37 | P1170: {=_xlfn.IFS(Deals[[#This Row],[Age]]<30,"Under 30",Deals[[#This Row],[Age]]<45,"30-44",TRUE,"45+")} -> 30-44 | Q1170: =IF(Deals[[#This Row],[Status]]="Pending","",Deals[[#This Row],[DecisionDate]]-Deals[[#This Row],[ApplicationDate]]) -> 25 | R1170: =IF(Deals[[#This Row],[Status]]="Approved",1,0) -> 0 | S1170: =IF(Deals[[#This Row],[IsApproved]]=1,Deals[[#This Row],[Amount]],0) -> 0 | T1170: =Deals[[#This Row],[ApprovedAmount]]*Deals[[#This Row],[ProfitRate]] -> 0
A1171: FN-01270 | B1171: 46271 | C1171: C0722 | D1171: Salmiya | E1171: Auto Murabaha | F1171: Online | G1171: 14100 | H1171: 0.0438 | I1171: 36 | J1171: OFF-SAL-1 | K1171: Approved | L1171: 46275 | M1171: =_xlfn.XLOOKUP(Deals[[#This Row],[CustomerID]],Customers!A:A,Customers!F:F) -> Mass | N1171: =_xlfn.XLOOKUP(Deals[[#This Row],[CustomerID]],Customers!A:A,Customers!E:E) -> Non-Kuwaiti | O1171: =2026-_xlfn.XLOOKUP(Deals[[#This Row],[CustomerID]],Customers!A:A,Customers!D:D) -> 61 | P1171: {=_xlfn.IFS(Deals[[#This Row],[Age]]<30,"Under 30",Deals[[#This Row],[Age]]<45,"30-44",TRUE,"45+")} -> 45+ | Q1171: =IF(Deals[[#This Row],[Status]]="Pending","",Deals[[#This Row],[DecisionDate]]-Deals[[#This Row],[ApplicationDate]]) -> 4 | R1171: =IF(Deals[[#This Row],[Status]]="Approved",1,0) -> 1 | S1171: =IF(Deals[[#This Row],[IsApproved]]=1,Deals[[#This Row],[Amount]],0) -> 14100 | T1171: =Deals[[#This Row],[ApprovedAmount]]*Deals[[#This Row],[ProfitRate]] -> 617.58
A1172: FN-01305 | B1172: 46271 | C1172: C0790 | D1172: Salmiya | E1172: Auto Murabaha | F1172: Mobile App | G1172: 16700 | H1172: 0.0493 | I1172: 60 | J1172: OFF-SAL-2 | K1172: Approved | L1172: 46272 | M1172: =_xlfn.XLOOKUP(Deals[[#This Row],[CustomerID]],Customers!A:A,Customers!F:F) -> Affluent | N1172: =_xlfn.XLOOKUP(Deals[[#This Row],[CustomerID]],Customers!A:A,Customers!E:E) -> Non-Kuwaiti | O1172: =2026-_xlfn.XLOOKUP(Deals[[#This Row],[CustomerID]],Customers!A:A,Customers!D:D) -> 39 | P1172: {=_xlfn.IFS(Deals[[#This Row],[Age]]<30,"Under 30",Deals[[#This Row],[Age]]<45,"30-44",TRUE,"45+")} -> 30-44 | Q1172: =IF(Deals[[#This Row],[Status]]="Pending","",Deals[[#This Row],[DecisionDate]]-Deals[[#This Row],[ApplicationDate]]) -> 1 | R1172: =IF(Deals[[#This Row],[Status]]="Approved",1,0) -> 1 | S1172: =IF(Deals[[#This Row],[IsApproved]]=1,Deals[[#This Row],[Amount]],0) -> 16700 | T1172: =Deals[[#This Row],[ApprovedAmount]]*Deals[[#This Row],[ProfitRate]] -> 823.31
A1173: FN-01165 | B1173: 46272 | C1173: C0490 | D1173: Kuwait City | E1173: Home Ijara | F1173: Branch | G1173: 177800 | H1173: 0.0438 | I1173: 180 | J1173: OFF-KUW-1 | K1173: Rejected | L1173: 46297 | M1173: =_xlfn.XLOOKUP(Deals[[#This Row],[CustomerID]],Customers!A:A,Customers!F:F) -> Mass | N1173: =_xlfn.XLOOKUP(Deals[[#This Row],[CustomerID]],Customers!A:A,Customers!E:E) -> Kuwaiti | O1173: =2026-_xlfn.XLOOKUP(Deals[[#This Row],[CustomerID]],Customers!A:A,Customers!D:D) -> 50 | P1173: {=_xlfn.IFS(Deals[[#This Row],[Age]]<30,"Under 30",Deals[[#This Row],[Age]]<45,"30-44",TRUE,"45+")} -> 45+ | Q1173: =IF(Deals[[#This Row],[Status]]="Pending","",Deals[[#This Row],[DecisionDate]]-Deals[[#This Row],[ApplicationDate]]) -> 25 | R1173: =IF(Deals[[#This Row],[Status]]="Approved",1,0) -> 0 | S1173: =IF(Deals[[#This Row],[IsApproved]]=1,Deals[[#This Row],[Amount]],0) -> 0 | T1173: =Deals[[#This Row],[ApprovedAmount]]*Deals[[#This Row],[ProfitRate]] -> 0
A1174: FN-01186 | B1174: 46272 | C1174: C0557 | D1174: Hawally | E1174: Auto Murabaha | F1174: Mobile App | G1174: 8700 | H1174: 0.0499 | I1174: 36 | J1174: OFF-HAW-1 | K1174: Approved | L1174: 46276 | M1174: =_xlfn.XLOOKUP(Deals[[#This Row],[CustomerID]],Customers!A:A,Customers!F:F) -> Affluent | N1174: =_xlfn.XLOOKUP(Deals[[#This Row],[CustomerID]],Customers!A:A,Customers!E:E) -> Kuwaiti | O1174: =2026-_xlfn.XLOOKUP(Deals[[#This Row],[CustomerID]],Customers!A:A,Customers!D:D) -> 33 | P1174: {=_xlfn.IFS(Deals[[#This Row],[Age]]<30,"Under 30",Deals[[#This Row],[Age]]<45,"30-44",TRUE,"45+")} -> 30-44 | Q1174: =IF(Deals[[#This Row],[Status]]="Pending","",Deals[[#This Row],[DecisionDate]]-Deals[[#This Row],[ApplicationDate]]) -> 4 | R1174: =IF(Deals[[#This Row],[Status]]="Approved",1,0) -> 1 | S1174: =IF(Deals[[#This Row],[IsApproved]]=1,Deals[[#This Row],[Amount]],0) -> 8700 | T1174: =Deals[[#This Row],[ApprovedAmount]]*Deals[[#This Row],[ProfitRate]] -> 434.13
A1175: FN-01216 | B1175: 46272 | C1175: C0209 | D1175: Kuwait City | E1175: Auto Murabaha | F1175: Online | G1175: 5800 | H1175: 0.0433 | I1175: 36 | J1175: OFF-KUW-2 | K1175: Pending | M1175: =_xlfn.XLOOKUP(Deals[[#This Row],[CustomerID]],Customers!A:A,Customers!F:F) -> Mass | N1175: =_xlfn.XLOOKUP(Deals[[#This Row],[CustomerID]],Customers!A:A,Customers!E:E) -> Kuwaiti | O1175: =2026-_xlfn.XLOOKUP(Deals[[#This Row],[CustomerID]],Customers!A:A,Customers!D:D) -> 30 | P1175: {=_xlfn.IFS(Deals[[#This Row],[Age]]<30,"Under 30",Deals[[#This Row],[Age]]<45,"30-44",TRUE,"45+")} -> 30-44 | Q1175: =IF(Deals[[#This Row],[Status]]="Pending","",Deals[[#This Row],[DecisionDate]]-Deals[[#This Row],[ApplicationDate]]) | R1175: =IF(Deals[[#This Row],[Status]]="Approved",1,0) -> 0 | S1175: =IF(Deals[[#This Row],[IsApproved]]=1,Deals[[#This Row],[Amount]],0) -> 0 | T1175: =Deals[[#This Row],[ApprovedAmount]]*Deals[[#This Row],[ProfitRate]] -> 0
...

Sheet Customers
A1: CustomerID | B1: CustomerName | C1: Gender | D1: BirthYear | E1: Nationality | F1: Segment | G1: JoinDate
A2: C0001 | B2: Noor Al-Kandari | C2: Female | D2: 1983 | E2: Kuwaiti | F2: Affluent | G2: 40950
A3: C0002 | B3: Omar Al-Ajmi | C3: Male | D3: 1975 | E3: Kuwaiti | F3: Mass | G3: 42150
A4: C0003 | B4: Fatima Al-Dosari | C4: Female | D4: 1998 | E4: Kuwaiti | F4: Mass | G4: 45318
A5: C0004 | B5: Ali Al-Sabah | C5: Male | D5: 1990 | E5: Kuwaiti | F5: Mass | G5: 44739
A6: C0005 | B6: Abdullah Al-Sabah | C6: Male | D6: 1984 | E6: Kuwaiti | F6: Mass | G6: 44768
A7: C0006 | B7: Mohammad Al-Fadhli | C7: Male | D7: 1990 | E7: Kuwaiti | F7: Mass | G7: 44666
A8: C0007 | B8: Ali Al-Harbi | C8: Male | D8: 1963 | E8: Kuwaiti | F8: Affluent | G8: 43681
A9: C0008 | B9: Reem Al-Fadhli | C9: Female | D9: 1990 | E9: Kuwaiti | F9: Mass | G9: 41651
A10: C0009 | B10: Mohammad Al-Shammari | C10: Male | D10: 1990 | E10: Kuwaiti | F10: Affluent | G10: 43855
A11: C0010 | B11: Mohammad Al-Azmi | C11: Male | D11: 1987 | E11: Kuwaiti | F11: Mass | G11: 44184
A12: C0011 | B12: Nasser Al-Kandari | C12: Male | D12: 1965 | E12: Kuwaiti | F12: Affluent | G12: 42749
A13: C0012 | B13: Aisha Al-Shammari | C13: Female | D13: 1987 | E13: Non-Kuwaiti | F13: Mass | G13: 40945
... A951: C0950 | B951: Noor Al-Hajri | C951: Female | D951: 1968 | E951: Non-Kuwaiti | F951: Affluent | G951: 41499

Sheet Deals_Raw
A1: DealID | B1: ApplicationDate | C1: CustomerID | D1: Branch | E1: Product | F1: Channel | G1: Amount | H1: ProfitRate | I1: TenorMonths | J1: Officer | K1: Status | L1: DecisionDate
A2: FN-00005 | B2: 46023 | C2: C0473 | D2: Kuwait City | E2: Personal Tawarruq | F2: Branch | G2: 25000 | H2: 0.0583 | I2: 12 | J2: OFF-KUW-1 | K2: Approved | L2: 46030
A3: FN-00013 | B3: 46023 | C3: C0939 | D3: Hawally | E3: Home Ijara | F3: Branch | G3: 122900 | H3: 0.0375 | I3: 120 | J3: OFF-HAW-3 | K3: Approved | L3: 46036
A4: FN-00017 | B4: 46023 | C4: C0035 | D4: Salmiya | E4: Personal Tawarruq | F4: Branch | G4: 23200 | H4: 0.0682 | I4: 12 | J4: OFF-SAL-1 | K4: Approved | L4: 46030
A5: FN-00019 | B5: 46023 | C5: C0228 | D5: Farwaniya | E5: Auto Murabaha | F5: Mobile App | G5: 11600 | H5: 0.0441 | I5: 48 | J5: OFF-FAR-2 | K5: Approved | L5: 46025
A6: FN-00048 | B6: 46023 | C6: C0904 | D6: Salmiya | E6: Personal Tawarruq | F6: Mobile App | G6: 24300 | H6: 0.0625 | I6: 60 | J6: OFF-SAL-1 | K6: Approved | L6: 46028
A7: FN-00077 | B7: 46023 | C7: C0890 | D7: Hawally | E7: Personal Tawarruq | F7: Branch | G7: 10600 | H7: 0.06 | I7: 36 | J7: OFF-HAW-1 | K7: Approved | L7: 46025
A8: FN-00012 | B8: 46024 | C8: C0294 | D8: Kuwait City | E8: Personal Tawarruq | F8: Branch | G8: 20300 | H8: 0.0638 | I8: 12 | J8: OFF-KUW-2 | K8: Approved | L8: 46025
A9: FN-00021 | B9: 46024 | C9: C0103 | D9: Hawally | E9: SME Murabaha | F9: Branch | G9: 55100 | H9: 0.076 | I9: 84 | J9: OFF-HAW-2 | K9: Rejected | L9: 46041
A10: FN-00080 | B10: 46024 | C10: C0911 | D10: Kuwait City | E10: Personal Tawarruq | F10: Branch | G10: 2000 | H10: 0.0552 | I10: 24 | J10: OFF-KUW-3 | K10: Approved | L10: 46031
A11: FN-00094 | B11: 46024 | C11: C0641 | D11: Hawally | E11: Auto Murabaha | F11: Mobile App | G11: 10600 | H11: 0.0472 | I11: 36 | J11: OFF-HAW-1 | K11: Approved | L11: 46028
A12: FN-00032 | B12: 46025 | C12: C0405 | D12: Ahmadi | E12: Auto Murabaha | F12: Online | G12: 9600 | H12: 0.042 | I12: 36 | J12: OFF-AHM-1 | K12: Approved | L12: 46029
A13: FN-00063 | B13: 46025 | C13: C0884 | D13: Hawally | E13: Personal Tawarruq | F13: Branch | G13: 12700 | H13: 0.0546 | I13: 24 | J13: OFF-HAW-3 | K13: Approved | L13: 46031
... A22: FN-00083 | B22: 46027 | C22: C0311 | D22: Hawally | E22: SME Murabaha | F22: Branch | G22: 55100 | H22: 0.0771 | I22: 60 | J22: OFF-HAW-2 | K22: Rejected | L22: 46038
A23: FN-00105 | B23: 46027 | C23: C0664 | D23: Kuwait City | E23: SME Murabaha | F23: Branch | H23: 0.0694 | I23: 36 | J23: OFF-KUW-2 | K23: Approved | L23: 46034
A24: FN-00108 | B24: 46027 | C24: C0727 | D24: Hawally | E24: SME Murabaha | F24: Branch | G24: 62100 | H24: 0.0565 | I24: 36 | J24: OFF-HAW-2 | K24: Rejected | L24: 46047
A25: FN-00022 | B25: 46028 | C25: C0022 | D25: Hawally | E25: Personal Tawaruq | F25: Branch | G25: 8900 | H25: 0.0555 | I25: 12 | J25: OFF-HAW-3 | K25: Approved | L25: 46029
A26: FN-00057 | B26: 46028 | C26: C0881 | D26: Hawally | E26: Auto Murabaha | F26: Branch | G26: 13400 | H26: 0.0353 | I26: 48 | J26: OFF-HAW-1 | K26: Rejected | L26: 46030
A27: FN-00075 | B27: 46028 | C27: C0465 | D27: Ahmadi | E27: Home Ijara | F27: Online | G27: 199400 | H27: 0.032 | I27: 120 | J27: OFF-AHM-1 | K27: Rejected | L27: 46050
A28: FN-00036 | B28: 46029 | C28: C0587 | D28: Jahra | E28: Auto Murabaha | F28: Branch | G28: 8800 | H28: 0.0415 | I28: 60 | J28: OFF-JAH-3 | K28: Approved | L28: 46032
A29: FN-00116 | B29: 46029 | C29: C0898 | D29: Kuwait City | E29: Personal Tawarruq | F29: Branch | G29: 16600 | H29: 0.0652 | I29: 48 | J29: OFF-KUW-1 | K29: Approved | L29: 46033
A30: FN-00029 | B30: 46030 | C30: C0078 | D30: Farwaniya | E30: Home Ijara | F30: Online | G30: 215000 | H30: 0.0432 | I30: 300 | J30: OFF-FAR-2 | K30: Approved | L30: 46054
A31: FN-00039 | B31: 46030 | C31: C0694 | D31: Jahra | E31: Home Ijara | F31: Branch | G31: 78800 | H31: 0.0374 | I31: 300 | J31: OFF-JAH-2 | K31: Approved | L31: 46050
A32: FN-00010 | B32: 46031 | C32: C0648 | D32: Kuwait City | E32: Personal Tawarruq | F32: Branch | G32: 20800 | H32: 0.0675 | I32: 24 | J32: OFF-KUW-1 | K32: Approved | L32: 46037
A33: FN-00020 | B33: 46031 | C33: C0321 | D33: Jahra | E33: Personal Tawarruq | F33: Branch | G33: 25000 | H33: 0.052 | I33: 36 | J33: OFF-JAH-3 | K33: Rejected | L33: 46035
A34: FN-00109 | B34: 46031 | C34: C0896 | D34: Jahra | E34: SME Murabaha | F34: Branch | G34: 105600 | H34: 0.0608 | I34: 60 | J34: OFF-JAH-1 | K34: Rejected | L34: 46051
A35: FN-00115 | B35: 46031 | C35: C0701 | D35: Hawally | E35: SME Murabaha | F35: Mobile App | G35: 60400 | H35: 0.0615 | I35: 36 | J35: OFF-HAW-3 | K35: Approved | L35: 46052
... A75: FN-00114 | B75: 46039 | C75: C0035 | D75: Salmiya | E75: Personal Tawarruq | F75: Branch | G75: 7700 | H75: 0.0673 | I75: 60 | J75: OFF-SAL-2 | K75: Approved | L75: 46041
A76: FN-00025 | B76: 46040 | C76: C0830 | D76: Jahra | E76: Personal Tawarruq | F76: Branch | G76: 9,100 KWD | H76: 0.0641 | I76: 60 | J76: OFF-JAH-1 | K76: Approved | L76: 46046
A77: FN-00001 | B77: 46041 | C77: C0451 | D77: Farwaniya | E77: Personal Tawarruq | F77: Branch | G77: 6400 | H77: 0.0696 | I77: 12 | J77: OFF-FAR-3 | K77: Rejected | L77: 46045
A78: FN-00002 | B78: 46041 | C78: C0446 | D78: Kuwait City | E78: Auto Murabaha | F78: Mobile App | G78: 7400 | H78: 0.0459 | I78: 36 | J78: OFF-KUW-3 | K78: Approved | L78: 46045
A79: FN-00028 | B79: 46041 | C79: C0406 | D79: Kuwait City | E79: Personal Tawarruq | F79: Online | G79: 24200 | H79: 0.0655 | I79: 12 | J79: OFF-KUW-1 | K79: Rejected | L79: 46045
A80: FN-00035 | B80: 46041 | C80: C0713 | D80: Salmiya | E80: Home Ijara | F80: Branch | G80: 142300 | H80: 0.0434 | I80: 300 | J80: OFF-SAL-1 | K80: Approved | L80: 46062
A81: FN-00111 | B81: 46041 | C81: C0913 | D81: Ahmadi | E81: Personal Tawarruq | F81: Mobile App | G81: 5700 | H81: 0.0639 | I81: 24 | J81: OFF-AHM-3 | K81: Approved | L81: 46045
A82: FN-00024 | B82: 46042 | C82: C0914 | D82: Hawally | E82: SME Murabaha | F82: Branch | G82: 80500 | H82: 0.0787 | I82: 36 | J82: OFF-HAW-1 | K82: Rejected | L82: 46061
A83: FN-00046 | B83: 46042 | C83: C0681 | D83: Salmiya | E83: SME Murabaha | F83: Branch | G83: 20,400 KWD | H83: 0.0669 | I83: 84 | J83: OFF-SAL-2 | K83: Rejected | L83: 46054
A84: FN-00011 | B84: 46043 | C84: C0003 | D84: Farwaniya | E84: Personal Tawarruq | F84: Branch | G84: 12200 | H84: 0.0565 | I84: 12 | J84: OFF-FAR-1 | K84: Approved | L84: 46046
A85: FN-00119 | B85: 46043 | C85: C0698 | D85: Farwaniya | E85: Personal Tawarruq | F85: Branch | G85: 17500 | H85: 0.065 | I85: 12 | J85: OFF-FAR-1 | K85: Approved | L85: 46046
A86: FN-00060 | B86: 46044 | C86: C0420 | D86: Farwaniya | E86: Auto Murabaha | F86: Branch | G86: 8400 | H86: 0.038 | I86: 60 | J86: OFF-FAR-2 | K86: Approved | L86: 46048
A87: FN-00084 | B87: 46044 | C87: C0747 | D87: Kuwait City | E87: SME Murabaha | F87: Branch | G87: 71000 | H87: 0.06 | I87: 60 | J87: OFF-KUW-1 | K87: Approved | L87: 46065
...

Sheet Rejected_Data
A1: DealID | B1: ApplicationDate | C1: CustomerID | D1: Branch | E1: Product | F1: Channel | G1: Amount | H1: ProfitRate | I1: TenorMonths | J1: Officer | K1: Status | L1: DecisionDate
A2: FN-00105 | B2: 46027 | C2: C0664 | D2: Kuwait City | E2: SME Murabaha | F2: Branch | H2: 0.0694 | I2: 36 | J2: OFF-KUW-2 | K2: Approved | L2: 46034
A3: FN-00156 | B3: 46081 | C3: C0440 | D3: Kuwait City | E3: Personal Tawarruq | F3: Mobile App | H3: 0.0609 | I3: 60 | J3: OFF-KUW-3 | K3: Approved | L3: 46084
A4: FN-00415 | B4: 46117 | C4: C0356 | D4: Kuwait City | E4: Personal Tawarruq | F4: Branch | H4: 0.0666 | I4: 60 | J4: OFF-KUW-1 | K4: Approved | L4: 46122
A5: FN-00559 | B5: 46148 | C5: C0534 | D5: Ahmadi | E5: SME Murabaha | F5: Mobile App | H5: 0.0758 | I5: 24 | J5: OFF-AHM-2 | K5: Rejected | L5: 46155
A6: FN-00599 | B6: 46149 | C6: C0781 | D6: Ahmadi | E6: Home Ijara | F6: Branch | H6: 0.0341 | I6: 180 | J6: OFF-AHM-3 | K6: Rejected | L6: 46161
A7: FN-00568 | B7: 46166 | C7: C0318 | D7: Hawally | E7: Auto Murabaha | F7: Mobile App | H7: 0.0363 | I7: 60 | J7: OFF-HAW-1 | K7: Approved | L7: 46169
A8: FN-00547 | B8: 46168 | C8: C0650 | D8: Salmiya | E8: SME Murabaha | F8: Branch | H8: 0.0699 | I8: 36 | J8: OFF-SAL-2 | K8: Approved | L8: 46181
A9: FN-01095 | B9: 46244 | C9: C0736 | D9: Hawally | E9: Auto Murabaha | F9: Online | H9: 0.0433 | I9: 36 | J9: OFF-HAW-1 | K9: Approved | L9: 46245
A10: FN-01061 | B10: 46252 | C10: C0078 | D10: Hawally | E10: Personal Tawarruq | F10: Branch | H10: 0.0646 | I10: 48 | J10: OFF-HAW-1 | K10: Rejected | L10: 46255
A11: FN-01239 | B11: 46266 | C11: C0023 | D11: Farwaniya | E11: Auto Murabaha | F11: Branch | H11: 0.0465 | I11: 60 | J11: OFF-FAR-1 | K11: Approved | L11: 46268
A12: FN-01298 | B12: 46288 | C12: C0645 | D12: Kuwait City | E12: Home Ijara | F12: Online | H12: 0.0344 | I12: 240 | J12: OFF-KUW-3 | K12: Pending
A13: FN-01253 | B13: 46295 | C13: C0260 | D13: Kuwait City | E13: Auto Murabaha | F13: Mobile App | H13: 0.0399 | I13: 36 | J13: OFF-KUW-2 | K13: Approved | L13: 46299
